2019-01-08T09:57:22.709582+00:00 app[web.1]: return self.model.objects.filter(session_key=session_key).exists()
2019-01-08T09:57:22.709584+00:00 app[web.1]: File "/app/.heroku/python/lib/python3.6/site-packages/django/db/models/query.py", line 715, in exists
2019-01-08T09:57:22.709585+00:00 app[web.1]: return self.query.has_results(using=self.db)
2019-01-08T09:57:22.709587+00:00 app[web.1]: File "/app/.heroku/python/lib/python3.6/site-packages/django/db/models/sql/query.py", line 509, in has_results
2019-01-08T09:57:22.709588+00:00 app[web.1]: return compiler.has_results()
2019-01-08T09:57:22.709590+00:00 app[web.1]: File "/app/.heroku/python/lib/python3.6/site-packages/django/db/models/sql/compiler.py", line 1037, in has_results
2019-01-08T09:57:22.709592+00:00 app[web.1]: return bool(self.execute_sql(SINGLE))
2019-01-08T09:57:22.709594+00:00 app[web.1]: File "/app/.heroku/python/lib/python3.6/site-packages/django/db/models/sql/compiler.py", line 1068, in execute_sql
2019-01-08T09:57:22.709596+00:00 app[web.1]: cursor.execute(sql, params)
2019-01-08T09:57:22.709598+00:00 app[web.1]: File "/app/.heroku/python/lib/python3.6/site-packages/django/db/backends/utils.py", line 68, in execute
2019-01-08T09:57:22.709601+00:00 app[web.1]: return self._execute_with_wrappers(sql, params, many=False, executor=self._execute)
2019-01-08T09:57:22.709611+00:00 app[web.1]: File "/app/.heroku/python/lib/python3.6/site-packages/django/db/backends/utils.py", line 77, in _execute_with_wrappers
2019-01-08T09:57:22.709613+00:00 app[web.1]: return executor(sql, params, many, context)
2019-01-08T09:57:22.709615+00:00 app[web.1]: File "/app/.heroku/python/lib/python3.6/site-packages/django/db/backends/utils.py", line 85, in _execute
2019-01-08T09:57:22.709617+00:00 app[web.1]: return self.cursor.execute(sql, params)
2019-01-08T09:57:22.709619+00:00 app[web.1]: File "/app/.heroku/python/lib/python3.6/site-packages/django/db/utils.py", line 89, in __exit__
2019-01-08T09:57:22.709621+00:00 app[web.1]: raise dj_exc_value.with_traceback(traceback) from exc_value
2019-01-08T09:57:22.709623+00:00 app[web.1]: File "/app/.heroku/python/lib/python3.6/site-packages/django/db/backends/utils.py", line 85, in _execute
2019-01-08T09:57:22.709625+00:00 app[web.1]: return self.cursor.execute(sql, params)
2019-01-08T09:57:22.709627+00:00 app[web.1]: django.db.utils.ProgrammingError: relation "django_session" does not exist
2019-01-08T09:57:22.709629+00:00 app[web.1]: LINE 1: SELECT (1) AS "a" FROM "django_session" WHERE "django_sessio...
2019-01-08T09:57:22.709631+00:00 app[web.1]: ^
2019-01-08T09:57:22.709633+00:00 app[web.1]: 
2019-01-08T09:57:34.822309+00:00 heroku[router]: at=info method=GET path="/" host=www.treeofknowledge.ai request_id=81764c68-26bc-48f5-9766-37197c7bc746 fwd="79.197.108.131" dyno=web.1 connect=1ms service=7ms status=200 bytes=10320 protocol=http
2019-01-08T09:57:47.170804+00:00 heroku[router]: at=info method=GET path="/static/images/dawn.png" host=www.treeofknowledge.ai request_id=a1b38bf7-d318-4af7-9621-8c1245007a33 fwd="79.197.108.131" dyno=web.1 connect=1ms service=45ms status=200 bytes=761715 protocol=http
2019-01-08T09:57:49.018900+00:00 heroku[router]: at=info method=GET path="/contact/" host=www.treeofknowledge.ai request_id=1e9106ed-cf13-43a0-aa71-1b5e31a69527 fwd="79.197.108.131" dyno=web.1 connect=1ms service=8ms status=200 bytes=4634 protocol=http
2019-01-08T09:57:49.781482+00:00 heroku[router]: at=info method=GET path="/static/images/deer_large.jpg" host=www.treeofknowledge.ai request_id=86e014fd-c80b-4d5a-aa42-0a1c34f760de fwd="79.197.108.131" dyno=web.1 connect=1ms service=23ms status=200 bytes=401160 protocol=http
2019-01-08T09:57:53.475293+00:00 heroku[router]: at=info method=GET path="/accounts/login/" host=www.treeofknowledge.ai request_id=c8725303-06a4-4a6d-8197-66b8286a6acd fwd="79.197.108.131" dyno=web.1 connect=0ms service=22ms status=200 bytes=3282 protocol=http
2019-01-08T09:58:04.334242+00:00 heroku[router]: at=info method=POST path="/accounts/login/" host=www.treeofknowledge.ai request_id=1afe0b0e-66fc-48df-85ac-daf426dd59ef fwd="79.197.108.131" dyno=web.1 connect=0ms service=210ms status=200 bytes=3600 protocol=http
2019-01-08T09:58:11.737738+00:00 heroku[router]: at=info method=GET path="/accounts/login/" host=www.treeofknowledge.ai request_id=b5d3b836-cb30-465d-a90b-ab2eab80a83f fwd="79.197.108.131" dyno=web.1 connect=0ms service=16ms status=200 bytes=3282 protocol=http
2019-01-08T09:58:59.443735+00:00 app[web.1]: ERROR:django.request:Internal Server Error: /accounts/register/
2019-01-08T09:58:59.443746+00:00 app[web.1]: Traceback (most recent call last):
2019-01-08T09:58:59.443749+00:00 app[web.1]: File "/app/.heroku/python/lib/python3.6/site-packages/django/db/backends/utils.py", line 85, in _execute
2019-01-08T09:58:59.443751+00:00 app[web.1]: return self.cursor.execute(sql, params)
2019-01-08T09:58:59.443752+00:00 app[web.1]: psycopg2.ProgrammingError: relation "django_session" does not exist
2019-01-08T09:58:59.443754+00:00 app[web.1]: LINE 1: SELECT (1) AS "a" FROM "django_session" WHERE "django_sessio...
2019-01-08T09:58:59.443756+00:00 app[web.1]: ^
2019-01-08T09:58:59.443758+00:00 app[web.1]: 
2019-01-08T09:58:59.443759+00:00 app[web.1]: 
2019-01-08T09:58:59.443761+00:00 app[web.1]: The above exception was the direct cause of the following exception:
2019-01-08T09:58:59.443762+00:00 app[web.1]: 
2019-01-08T09:58:59.443764+00:00 app[web.1]: Traceback (most recent call last):
2019-01-08T09:58:59.443766+00:00 app[web.1]: File "/app/.heroku/python/lib/python3.6/site-packages/django/core/handlers/exception.py", line 35, in inner
2019-01-08T09:58:59.443767+00:00 app[web.1]: response = get_response(request)
2019-01-08T09:58:59.443769+00:00 app[web.1]: File "/app/.heroku/python/lib/python3.6/site-packages/django/core/handlers/base.py", line 128, in _get_response
2019-01-08T09:58:59.443771+00:00 app[web.1]: response = self.process_exception_by_middleware(e, request)
2019-01-08T09:58:59.443773+00:00 app[web.1]: File "/app/.heroku/python/lib/python3.6/site-packages/django/core/handlers/base.py", line 126, in _get_response
2019-01-08T09:58:59.443775+00:00 app[web.1]: response = wrapped_callback(request, *callback_args, **callback_kwargs)
2019-01-08T09:58:59.443776+00:00 app[web.1]: File "/app/.heroku/python/lib/python3.6/site-packages/django/views/generic/base.py", line 69, in view
2019-01-08T09:58:59.443778+00:00 app[web.1]: return self.dispatch(request, *args, **kwargs)
2019-01-08T09:58:59.443780+00:00 app[web.1]: File "/app/.heroku/python/lib/python3.6/site-packages/django/utils/decorators.py", line 62, in _wrapper
2019-01-08T09:58:59.443781+00:00 app[web.1]: return bound_func(*args, **kwargs)
2019-01-08T09:58:59.443784+00:00 app[web.1]: File "/app/.heroku/python/lib/python3.6/site-packages/django/views/decorators/debug.py", line 76, in sensitive_post_parameters_wrapper
2019-01-08T09:58:59.443785+00:00 app[web.1]: return view(request, *args, **kwargs)
2019-01-08T09:58:59.443787+00:00 app[web.1]: File "/app/.heroku/python/lib/python3.6/site-packages/django/utils/decorators.py", line 58, in bound_func
2019-01-08T09:58:59.443789+00:00 app[web.1]: return func.__get__(self, type(self))(*args2, **kwargs2)
2019-01-08T09:58:59.443790+00:00 app[web.1]: File "/app/.heroku/python/lib/python3.6/site-packages/registration/views.py", line 53, in dispatch
2019-01-08T09:58:59.443792+00:00 app[web.1]: return super(RegistrationView, self).dispatch(request, *args, **kwargs)
2019-01-08T09:58:59.443793+00:00 app[web.1]: File "/app/.heroku/python/lib/python3.6/site-packages/django/views/generic/base.py", line 89, in dispatch
2019-01-08T09:58:59.443795+00:00 app[web.1]: return handler(request, *args, **kwargs)
2019-01-08T09:58:59.443797+00:00 app[web.1]: File "/app/.heroku/python/lib/python3.6/site-packages/django/views/generic/edit.py", line 142, in post
2019-01-08T09:58:59.443798+00:00 app[web.1]: return self.form_valid(form)
2019-01-08T09:58:59.443800+00:00 app[web.1]: File "/app/.heroku/python/lib/python3.6/site-packages/registration/views.py", line 56, in form_valid
2019-01-08T09:58:59.443802+00:00 app[web.1]: new_user = self.register(form)
2019-01-08T09:58:59.443804+00:00 app[web.1]: File "/app/.heroku/python/lib/python3.6/site-packages/registration/backends/simple/views.py", line 27, in register
2019-01-08T09:58:59.443805+00:00 app[web.1]: login(self.request, new_user)
2019-01-08T09:58:59.443807+00:00 app[web.1]: File "/app/.heroku/python/lib/python3.6/site-packages/django/contrib/auth/__init__.py", line 140, in login
2019-01-08T09:58:59.443809+00:00 app[web.1]: request.session.cycle_key()
2019-01-08T09:58:59.443811+00:00 app[web.1]: File "/app/.heroku/python/lib/python3.6/site-packages/django/contrib/sessions/backends/base.py", line 300, in cycle_key
2019-01-08T09:58:59.443813+00:00 app[web.1]: self.create()
2019-01-08T09:58:59.443814+00:00 app[web.1]: File "/app/.heroku/python/lib/python3.6/site-packages/django/contrib/sessions/backends/db.py", line 49, in create
2019-01-08T09:58:59.443816+00:00 app[web.1]: self._session_key = self._get_new_session_key()
2019-01-08T09:58:59.443818+00:00 app[web.1]: File "/app/.heroku/python/lib/python3.6/site-packages/django/contrib/sessions/backends/base.py", line 153, in _get_new_session_key
2019-01-08T09:58:59.443819+00:00 app[web.1]: if not self.exists(session_key):
2019-01-08T09:58:59.443821+00:00 app[web.1]: File "/app/.heroku/python/lib/python3.6/site-packages/django/contrib/sessions/backends/db.py", line 45, in exists
2019-01-08T09:58:59.443823+00:00 app[web.1]: return self.model.objects.filter(session_key=session_key).exists()
2019-01-08T09:58:59.443824+00:00 app[web.1]: File "/app/.heroku/python/lib/python3.6/site-packages/django/db/models/query.py", line 715, in exists
2019-01-08T09:58:59.443826+00:00 app[web.1]: return self.query.has_results(using=self.db)
2019-01-08T09:58:59.443828+00:00 app[web.1]: File "/app/.heroku/python/lib/python3.6/site-packages/django/db/models/sql/query.py", line 509, in has_results
2019-01-08T09:58:59.443830+00:00 app[web.1]: return compiler.has_results()
2019-01-08T09:58:59.443831+00:00 app[web.1]: File "/app/.heroku/python/lib/python3.6/site-packages/django/db/models/sql/compiler.py", line 1037, in has_results
2019-01-08T09:58:59.443833+00:00 app[web.1]: return bool(self.execute_sql(SINGLE))
2019-01-08T09:58:59.443835+00:00 app[web.1]: File "/app/.heroku/python/lib/python3.6/site-packages/django/db/models/sql/compiler.py", line 1068, in execute_sql
2019-01-08T09:58:59.443836+00:00 app[web.1]: cursor.execute(sql, params)
2019-01-08T09:58:59.443838+00:00 app[web.1]: File "/app/.heroku/python/lib/python3.6/site-packages/django/db/backends/utils.py", line 68, in execute
2019-01-08T09:58:59.443840+00:00 app[web.1]: return self._execute_with_wrappers(sql, params, many=False, executor=self._execute)
2019-01-08T09:58:59.443849+00:00 app[web.1]: File "/app/.heroku/python/lib/python3.6/site-packages/django/db/backends/utils.py", line 77, in _execute_with_wrappers
2019-01-08T09:58:59.443851+00:00 app[web.1]: return executor(sql, params, many, context)
2019-01-08T09:58:59.443853+00:00 app[web.1]: File "/app/.heroku/python/lib/python3.6/site-packages/django/db/backends/utils.py", line 85, in _execute
2019-01-08T09:58:59.443855+00:00 app[web.1]: return self.cursor.execute(sql, params)
2019-01-08T09:58:59.443856+00:00 app[web.1]: File "/app/.heroku/python/lib/python3.6/site-packages/django/db/utils.py", line 89, in __exit__
2019-01-08T09:58:59.443858+00:00 app[web.1]: raise dj_exc_value.with_traceback(traceback) from exc_value
2019-01-08T09:58:59.443860+00:00 app[web.1]: File "/app/.heroku/python/lib/python3.6/site-packages/django/db/backends/utils.py", line 85, in _execute
2019-01-08T09:58:59.443862+00:00 app[web.1]: return self.cursor.execute(sql, params)
2019-01-08T09:58:59.443863+00:00 app[web.1]: django.db.utils.ProgrammingError: relation "django_session" does not exist
2019-01-08T09:58:59.443865+00:00 app[web.1]: LINE 1: SELECT (1) AS "a" FROM "django_session" WHERE "django_sessio...
2019-01-08T09:58:59.443866+00:00 app[web.1]: ^
2019-01-08T09:58:59.443935+00:00 app[web.1]: 
2019-01-08T09:59:00.096126+00:00 heroku[router]: at=info method=GET path="/accounts/static/images/biever.jpg" host=www.treeofknowledge.ai request_id=ed6bfc6d-ecef-4ecb-89aa-3f5b474a401d fwd="79.197.108.131" dyno=web.1 connect=1ms service=42ms status=404 bytes=3007 protocol=http
2019-01-08T09:59:00.092564+00:00 app[web.1]: WARNING:django.request:Not Found: /accounts/static/images/biever.jpg
