2019-01-08T13:32:06.468915+00:00 heroku[router]: at=info method=GET path="/tool/main_menu/" host=www.treeofknowledge.ai request_id=4b6e7f6b-6f8c-4b65-bdf7-c6399e5bfe9c fwd="79.197.108.131" dyno=web.1 connect=1ms service=92ms status=500 bytes=3008 protocol=http
2019-01-08T13:32:07.003896+00:00 heroku[router]: at=info method=GET path="/tool/static/images/biever.jpg" host=www.treeofknowledge.ai request_id=2916752a-b327-4616-956f-65b6672091e2 fwd="79.197.108.131" dyno=web.1 connect=1ms service=9ms status=404 bytes=3007 protocol=http
2019-01-08T13:32:10.965954+00:00 heroku[router]: at=info method=GET path="/accounts/register/" host=www.treeofknowledge.ai request_id=2c877c11-a3ff-4bad-b0aa-be1b698e3ca9 fwd="79.197.108.131" dyno=web.1 connect=1ms service=33ms status=302 bytes=226 protocol=http
2019-01-08T13:32:11.188563+00:00 app[web.1]: !!!!!!!!!   MAIN MENU IS CALLED  !!!!!!!!!
2019-01-08T13:32:11.188846+00:00 app[web.1]: !!!!!!!!!   EXISTING MODELS WERE FOUND  !!!!!!!!!
2019-01-08T13:32:11.235760+00:00 app[web.1]: ERROR:django.request:Internal Server Error: /tool/main_menu/
2019-01-08T13:32:11.235770+00:00 app[web.1]: Traceback (most recent call last):
2019-01-08T13:32:11.235773+00:00 app[web.1]: File "/app/.heroku/python/lib/python3.6/site-packages/django/db/backends/utils.py", line 85, in _execute
2019-01-08T13:32:11.235774+00:00 app[web.1]: return self.cursor.execute(sql, params)
2019-01-08T13:32:11.235777+00:00 app[web.1]: psycopg2.ProgrammingError: column collection_simulation_model.is_private does not exist
2019-01-08T13:32:11.235779+00:00 app[web.1]: LINE 1: ...pdated", "collection_simulation_model"."user_id", "collectio...
2019-01-08T13:32:11.235780+00:00 app[web.1]: ^
2019-01-08T13:32:11.235782+00:00 app[web.1]: 
2019-01-08T13:32:11.235784+00:00 app[web.1]: 
2019-01-08T13:32:11.235786+00:00 app[web.1]: The above exception was the direct cause of the following exception:
2019-01-08T13:32:11.235788+00:00 app[web.1]: 
2019-01-08T13:32:11.235789+00:00 app[web.1]: Traceback (most recent call last):
2019-01-08T13:32:11.235791+00:00 app[web.1]: File "/app/.heroku/python/lib/python3.6/site-packages/django/core/handlers/exception.py", line 35, in inner
2019-01-08T13:32:11.235792+00:00 app[web.1]: response = get_response(request)
2019-01-08T13:32:11.235794+00:00 app[web.1]: File "/app/.heroku/python/lib/python3.6/site-packages/django/core/handlers/base.py", line 128, in _get_response
2019-01-08T13:32:11.235796+00:00 app[web.1]: response = self.process_exception_by_middleware(e, request)
2019-01-08T13:32:11.235797+00:00 app[web.1]: File "/app/.heroku/python/lib/python3.6/site-packages/django/core/handlers/base.py", line 126, in _get_response
2019-01-08T13:32:11.235799+00:00 app[web.1]: response = wrapped_callback(request, *callback_args, **callback_kwargs)
2019-01-08T13:32:11.235801+00:00 app[web.1]: File "/app/.heroku/python/lib/python3.6/site-packages/django/contrib/auth/decorators.py", line 21, in _wrapped_view
2019-01-08T13:32:11.235802+00:00 app[web.1]: return view_func(request, *args, **kwargs)
2019-01-08T13:32:11.235804+00:00 app[web.1]: File "/app/collection/views.py", line 68, in main_menu
2019-01-08T13:32:11.235806+00:00 app[web.1]: print("!!!!!!!!!   NUMBER OF EXISTING MODELS: %s  !!!!!!!!!" % len(models))
2019-01-08T13:32:11.235808+00:00 app[web.1]: File "/app/.heroku/python/lib/python3.6/site-packages/django/db/models/query.py", line 254, in __len__
2019-01-08T13:32:11.235814+00:00 app[web.1]: self._fetch_all()
2019-01-08T13:32:11.235816+00:00 app[web.1]: File "/app/.heroku/python/lib/python3.6/site-packages/django/db/models/query.py", line 1179, in _fetch_all
2019-01-08T13:32:11.235817+00:00 app[web.1]: self._result_cache = list(self._iterable_class(self))
2019-01-08T13:32:11.235819+00:00 app[web.1]: File "/app/.heroku/python/lib/python3.6/site-packages/django/db/models/query.py", line 53, in __iter__
2019-01-08T13:32:11.235821+00:00 app[web.1]: results = compiler.execute_sql(chunked_fetch=self.chunked_fetch, chunk_size=self.chunk_size)
2019-01-08T13:32:11.235822+00:00 app[web.1]: File "/app/.heroku/python/lib/python3.6/site-packages/django/db/models/sql/compiler.py", line 1068, in execute_sql
2019-01-08T13:32:11.235824+00:00 app[web.1]: cursor.execute(sql, params)
2019-01-08T13:32:11.235825+00:00 app[web.1]: File "/app/.heroku/python/lib/python3.6/site-packages/django/db/backends/utils.py", line 68, in execute
2019-01-08T13:32:11.235827+00:00 app[web.1]: return self._execute_with_wrappers(sql, params, many=False, executor=self._execute)
2019-01-08T13:32:11.235829+00:00 app[web.1]: File "/app/.heroku/python/lib/python3.6/site-packages/django/db/backends/utils.py", line 77, in _execute_with_wrappers
2019-01-08T13:32:11.235830+00:00 app[web.1]: return executor(sql, params, many, context)
2019-01-08T13:32:11.235832+00:00 app[web.1]: File "/app/.heroku/python/lib/python3.6/site-packages/django/db/backends/utils.py", line 85, in _execute
2019-01-08T13:32:11.235834+00:00 app[web.1]: return self.cursor.execute(sql, params)
2019-01-08T13:32:11.235836+00:00 app[web.1]: File "/app/.heroku/python/lib/python3.6/site-packages/django/db/utils.py", line 89, in __exit__
2019-01-08T13:32:11.235838+00:00 app[web.1]: raise dj_exc_value.with_traceback(traceback) from exc_value
2019-01-08T13:32:11.235839+00:00 app[web.1]: File "/app/.heroku/python/lib/python3.6/site-packages/django/db/backends/utils.py", line 85, in _execute
2019-01-08T13:32:11.235841+00:00 app[web.1]: return self.cursor.execute(sql, params)
2019-01-08T13:32:11.235843+00:00 app[web.1]: django.db.utils.ProgrammingError: column collection_simulation_model.is_private does not exist
2019-01-08T13:32:11.235845+00:00 app[web.1]: LINE 1: ...pdated", "collection_simulation_model"."user_id", "collectio...
2019-01-08T13:32:11.235846+00:00 app[web.1]: ^
2019-01-08T13:32:11.235897+00:00 app[web.1]: 
2019-01-08T13:32:12.319102+00:00 app[web.1]: WARNING:django.request:Not Found: /tool/static/images/biever.jpg
2019-01-08T13:32:15.551070+00:00 heroku[router]: at=info method=GET path="/accounts/login/" host=www.treeofknowledge.ai request_id=bc43ed0c-e3a3-4473-b021-8592b005116b fwd="79.197.108.131" dyno=web.1 connect=1ms service=19ms status=200 bytes=3282 protocol=http
2019-01-08T13:32:40.813920+00:00 heroku[router]: at=info method=GET path="/accounts/register/" host=www.treeofknowledge.ai request_id=199be5a3-200a-4431-b7c5-462a0e5a4796 fwd="79.197.108.131" dyno=web.1 connect=1ms service=61ms status=302 bytes=226 protocol=http
2019-01-08T13:32:41.052811+00:00 app[web.1]: !!!!!!!!!   MAIN MENU IS CALLED  !!!!!!!!!
2019-01-08T13:32:41.053129+00:00 app[web.1]: !!!!!!!!!   EXISTING MODELS WERE FOUND  !!!!!!!!!
2019-01-08T13:32:41.154186+00:00 app[web.1]: ERROR:django.request:Internal Server Error: /tool/main_menu/
2019-01-08T13:32:41.154190+00:00 app[web.1]: Traceback (most recent call last):
2019-01-08T13:32:41.154196+00:00 app[web.1]: File "/app/.heroku/python/lib/python3.6/site-packages/django/db/backends/utils.py", line 85, in _execute
2019-01-08T13:32:41.154198+00:00 app[web.1]: return self.cursor.execute(sql, params)
2019-01-08T13:32:41.154201+00:00 app[web.1]: psycopg2.ProgrammingError: column collection_simulation_model.is_private does not exist
2019-01-08T13:32:41.154204+00:00 app[web.1]: LINE 1: ...pdated", "collection_simulation_model"."user_id", "collectio...
2019-01-08T13:32:41.154205+00:00 app[web.1]: ^
2019-01-08T13:32:41.154208+00:00 app[web.1]: 
2019-01-08T13:32:41.154209+00:00 app[web.1]: 
2019-01-08T13:32:41.154211+00:00 app[web.1]: The above exception was the direct cause of the following exception:
2019-01-08T13:32:41.154213+00:00 app[web.1]: 
2019-01-08T13:32:41.154214+00:00 app[web.1]: Traceback (most recent call last):
2019-01-08T13:32:41.154216+00:00 app[web.1]: File "/app/.heroku/python/lib/python3.6/site-packages/django/core/handlers/exception.py", line 35, in inner
2019-01-08T13:32:41.154218+00:00 app[web.1]: response = get_response(request)
2019-01-08T13:32:41.154221+00:00 app[web.1]: File "/app/.heroku/python/lib/python3.6/site-packages/django/core/handlers/base.py", line 128, in _get_response
2019-01-08T13:32:41.154222+00:00 app[web.1]: response = self.process_exception_by_middleware(e, request)
2019-01-08T13:32:41.154224+00:00 app[web.1]: File "/app/.heroku/python/lib/python3.6/site-packages/django/core/handlers/base.py", line 126, in _get_response
2019-01-08T13:32:41.154225+00:00 app[web.1]: response = wrapped_callback(request, *callback_args, **callback_kwargs)
2019-01-08T13:32:41.154227+00:00 app[web.1]: File "/app/.heroku/python/lib/python3.6/site-packages/django/contrib/auth/decorators.py", line 21, in _wrapped_view
2019-01-08T13:32:41.154228+00:00 app[web.1]: return view_func(request, *args, **kwargs)
2019-01-08T13:32:41.154230+00:00 app[web.1]: File "/app/collection/views.py", line 68, in main_menu
2019-01-08T13:32:41.154232+00:00 app[web.1]: print("!!!!!!!!!   NUMBER OF EXISTING MODELS: %s  !!!!!!!!!" % len(models))
2019-01-08T13:32:41.154233+00:00 app[web.1]: File "/app/.heroku/python/lib/python3.6/site-packages/django/db/models/query.py", line 254, in __len__
2019-01-08T13:32:41.154236+00:00 app[web.1]: self._fetch_all()
2019-01-08T13:32:41.154238+00:00 app[web.1]: File "/app/.heroku/python/lib/python3.6/site-packages/django/db/models/query.py", line 1179, in _fetch_all
2019-01-08T13:32:41.154239+00:00 app[web.1]: self._result_cache = list(self._iterable_class(self))
2019-01-08T13:32:41.154241+00:00 app[web.1]: File "/app/.heroku/python/lib/python3.6/site-packages/django/db/models/query.py", line 53, in __iter__
2019-01-08T13:32:41.154242+00:00 app[web.1]: results = compiler.execute_sql(chunked_fetch=self.chunked_fetch, chunk_size=self.chunk_size)
2019-01-08T13:32:41.154244+00:00 app[web.1]: File "/app/.heroku/python/lib/python3.6/site-packages/django/db/models/sql/compiler.py", line 1068, in execute_sql
2019-01-08T13:32:41.154245+00:00 app[web.1]: cursor.execute(sql, params)
2019-01-08T13:32:41.154247+00:00 app[web.1]: File "/app/.heroku/python/lib/python3.6/site-packages/django/db/backends/utils.py", line 68, in execute
2019-01-08T13:32:41.154249+00:00 app[web.1]: return self._execute_with_wrappers(sql, params, many=False, executor=self._execute)
2019-01-08T13:32:41.154251+00:00 app[web.1]: File "/app/.heroku/python/lib/python3.6/site-packages/django/db/backends/utils.py", line 77, in _execute_with_wrappers
2019-01-08T13:32:41.154252+00:00 app[web.1]: return executor(sql, params, many, context)
2019-01-08T13:32:41.154254+00:00 app[web.1]: File "/app/.heroku/python/lib/python3.6/site-packages/django/db/backends/utils.py", line 85, in _execute
2019-01-08T13:32:41.154255+00:00 app[web.1]: return self.cursor.execute(sql, params)
2019-01-08T13:32:41.154257+00:00 app[web.1]: File "/app/.heroku/python/lib/python3.6/site-packages/django/db/utils.py", line 89, in __exit__
2019-01-08T13:32:41.154259+00:00 app[web.1]: raise dj_exc_value.with_traceback(traceback) from exc_value
2019-01-08T13:32:41.154260+00:00 app[web.1]: File "/app/.heroku/python/lib/python3.6/site-packages/django/db/backends/utils.py", line 85, in _execute
2019-01-08T13:32:41.154262+00:00 app[web.1]: return self.cursor.execute(sql, params)
2019-01-08T13:32:41.154263+00:00 app[web.1]: django.db.utils.ProgrammingError: column collection_simulation_model.is_private does not exist
2019-01-08T13:32:41.154265+00:00 app[web.1]: LINE 1: ...pdated", "collection_simulation_model"."user_id", "collectio...
2019-01-08T13:32:41.154266+00:00 app[web.1]: ^
2019-01-08T13:32:41.154277+00:00 app[web.1]: 
2019-01-08T13:32:41.166087+00:00 heroku[router]: at=info method=GET path="/tool/main_menu/" host=www.treeofknowledge.ai request_id=cc547750-4c30-4009-8d0d-e75fbd75346c fwd="79.197.108.131" dyno=web.1 connect=1ms service=171ms status=500 bytes=3008 protocol=http
2019-01-08T13:32:41.987447+00:00 heroku[router]: at=info method=GET path="/tool/static/images/biever.jpg" host=www.treeofknowledge.ai request_id=4b6056cb-b385-421f-909a-722847034504 fwd="79.197.108.131" dyno=web.1 connect=1ms service=12ms status=404 bytes=3007 protocol=http
