2019-01-08T13:51:34.233278+00:00 heroku[run.8460]: Process exited with status 0
2019-01-08T13:51:50.017110+00:00 heroku[router]: at=info method=GET path="/static/css/landing_page.59d4ed3d022c.css" host=www.treeofknowledge.ai request_id=3a9f2a99-340e-419a-bf5e-489a3b6061fa fwd="79.197.108.131" dyno=web.1 connect=0ms service=2ms status=200 bytes=1542 protocol=http
2019-01-08T13:51:52.928841+00:00 heroku[router]: at=info method=GET path="/accounts/register/" host=www.treeofknowledge.ai request_id=e4319572-95ba-4306-aa91-d5798442a8a9 fwd="79.197.108.131" dyno=web.1 connect=0ms service=21ms status=302 bytes=226 protocol=http
2019-01-08T13:51:53.112904+00:00 app[web.1]: !!!!!!!!!   MAIN MENU IS CALLED  !!!!!!!!!
2019-01-08T13:51:53.112966+00:00 app[web.1]: !!!!!!!!!   EXISTING MODELS WERE FOUND  !!!!!!!!!
2019-01-08T13:51:53.141716+00:00 app[web.1]: ERROR:django.request:Internal Server Error: /tool/main_menu/
2019-01-08T13:51:53.141720+00:00 app[web.1]: Traceback (most recent call last):
2019-01-08T13:51:53.141728+00:00 app[web.1]: File "/app/.heroku/python/lib/python3.6/site-packages/django/db/backends/utils.py", line 85, in _execute
2019-01-08T13:51:53.141730+00:00 app[web.1]: return self.cursor.execute(sql, params)
2019-01-08T13:51:53.141733+00:00 app[web.1]: psycopg2.ProgrammingError: column collection_simulation_model.is_private does not exist
2019-01-08T13:51:53.141736+00:00 app[web.1]: LINE 1: ...pdated", "collection_simulation_model"."user_id", "collectio...
2019-01-08T13:51:53.141737+00:00 app[web.1]: ^
2019-01-08T13:51:53.141740+00:00 app[web.1]: 
2019-01-08T13:51:53.141742+00:00 app[web.1]: 
2019-01-08T13:51:53.141743+00:00 app[web.1]: The above exception was the direct cause of the following exception:
2019-01-08T13:51:53.141744+00:00 app[web.1]: 
2019-01-08T13:51:53.141745+00:00 app[web.1]: Traceback (most recent call last):
2019-01-08T13:51:53.141746+00:00 app[web.1]: File "/app/.heroku/python/lib/python3.6/site-packages/django/core/handlers/exception.py", line 35, in inner
2019-01-08T13:51:53.141747+00:00 app[web.1]: response = get_response(request)
2019-01-08T13:51:53.141751+00:00 app[web.1]: File "/app/.heroku/python/lib/python3.6/site-packages/django/core/handlers/base.py", line 128, in _get_response
2019-01-08T13:51:53.141752+00:00 app[web.1]: response = self.process_exception_by_middleware(e, request)
2019-01-08T13:51:53.141753+00:00 app[web.1]: File "/app/.heroku/python/lib/python3.6/site-packages/django/core/handlers/base.py", line 126, in _get_response
2019-01-08T13:51:53.141754+00:00 app[web.1]: response = wrapped_callback(request, *callback_args, **callback_kwargs)
2019-01-08T13:51:53.141756+00:00 app[web.1]: File "/app/.heroku/python/lib/python3.6/site-packages/django/contrib/auth/decorators.py", line 21, in _wrapped_view
2019-01-08T13:51:53.141757+00:00 app[web.1]: return view_func(request, *args, **kwargs)
2019-01-08T13:51:53.141758+00:00 app[web.1]: File "/app/collection/views.py", line 68, in main_menu
2019-01-08T13:51:53.141759+00:00 app[web.1]: print("!!!!!!!!!   NUMBER OF EXISTING MODELS: %s  !!!!!!!!!" % len(models))
2019-01-08T13:51:53.141760+00:00 app[web.1]: File "/app/.heroku/python/lib/python3.6/site-packages/django/db/models/query.py", line 254, in __len__
2019-01-08T13:51:53.141762+00:00 app[web.1]: self._fetch_all()
2019-01-08T13:51:53.141763+00:00 app[web.1]: File "/app/.heroku/python/lib/python3.6/site-packages/django/db/models/query.py", line 1179, in _fetch_all
2019-01-08T13:51:53.141764+00:00 app[web.1]: self._result_cache = list(self._iterable_class(self))
2019-01-08T13:51:53.141765+00:00 app[web.1]: File "/app/.heroku/python/lib/python3.6/site-packages/django/db/models/query.py", line 53, in __iter__
2019-01-08T13:51:53.141766+00:00 app[web.1]: results = compiler.execute_sql(chunked_fetch=self.chunked_fetch, chunk_size=self.chunk_size)
2019-01-08T13:51:53.141767+00:00 app[web.1]: File "/app/.heroku/python/lib/python3.6/site-packages/django/db/models/sql/compiler.py", line 1068, in execute_sql
2019-01-08T13:51:53.141768+00:00 app[web.1]: cursor.execute(sql, params)
2019-01-08T13:51:53.141770+00:00 app[web.1]: File "/app/.heroku/python/lib/python3.6/site-packages/django/db/backends/utils.py", line 68, in execute
2019-01-08T13:51:53.141771+00:00 app[web.1]: return self._execute_with_wrappers(sql, params, many=False, executor=self._execute)
2019-01-08T13:51:53.141772+00:00 app[web.1]: File "/app/.heroku/python/lib/python3.6/site-packages/django/db/backends/utils.py", line 77, in _execute_with_wrappers
2019-01-08T13:51:53.141773+00:00 app[web.1]: return executor(sql, params, many, context)
2019-01-08T13:51:53.141774+00:00 app[web.1]: File "/app/.heroku/python/lib/python3.6/site-packages/django/db/backends/utils.py", line 85, in _execute
2019-01-08T13:51:53.141775+00:00 app[web.1]: return self.cursor.execute(sql, params)
2019-01-08T13:51:53.141776+00:00 app[web.1]: File "/app/.heroku/python/lib/python3.6/site-packages/django/db/utils.py", line 89, in __exit__
2019-01-08T13:51:53.141777+00:00 app[web.1]: raise dj_exc_value.with_traceback(traceback) from exc_value
2019-01-08T13:51:53.141778+00:00 app[web.1]: File "/app/.heroku/python/lib/python3.6/site-packages/django/db/backends/utils.py", line 85, in _execute
2019-01-08T13:51:53.141779+00:00 app[web.1]: return self.cursor.execute(sql, params)
2019-01-08T13:51:53.141780+00:00 app[web.1]: django.db.utils.ProgrammingError: column collection_simulation_model.is_private does not exist
2019-01-08T13:51:53.141781+00:00 app[web.1]: LINE 1: ...pdated", "collection_simulation_model"."user_id", "collectio...
2019-01-08T13:51:53.141783+00:00 app[web.1]: ^
2019-01-08T13:51:53.141788+00:00 app[web.1]: 
2019-01-08T13:51:53.145961+00:00 heroku[router]: at=info method=GET path="/tool/main_menu/" host=www.treeofknowledge.ai request_id=4b43b878-fc65-44ab-a5be-0cb35d216d7f fwd="79.197.108.131" dyno=web.1 connect=0ms service=54ms status=500 bytes=3008 protocol=http
2019-01-08T13:51:54.028757+00:00 heroku[router]: at=info method=GET path="/static/images/logo.4af604e4f42e.png" host=www.treeofknowledge.ai request_id=331b22cd-b0cc-499b-94a6-7b10c2af8e79 fwd="79.197.108.131" dyno=web.1 connect=0ms service=4ms status=200 bytes=60394 protocol=http
2019-01-08T13:52:02.064254+00:00 heroku[router]: at=info method=GET path="/accounts/login/" host=www.treeofknowledge.ai request_id=68ece65d-b22f-4aa1-bddc-3eeceeb539a3 fwd="79.197.108.131" dyno=web.1 connect=0ms service=8ms status=200 bytes=3282 protocol=http
2019-01-08T13:52:02.397345+00:00 heroku[router]: at=info method=GET path="/static/css/registration_pages.994e8a867b91.css" host=www.treeofknowledge.ai request_id=197c8a01-6bd2-4cdb-a7bd-ba297af6d0e4 fwd="79.197.108.131" dyno=web.1 connect=0ms service=2ms status=200 bytes=1202 protocol=http
2019-01-08T13:52:23.073473+00:00 heroku[router]: at=info method=GET path="/tool/main_menu/" host=www.treeofknowledge.ai request_id=8198e628-79d5-4f0d-8c49-1b608376368e fwd="79.197.108.131" dyno=web.1 connect=0ms service=116ms status=500 bytes=3008 protocol=http
2019-01-08T13:52:22.988054+00:00 app[web.1]: !!!!!!!!!   MAIN MENU IS CALLED  !!!!!!!!!
2019-01-08T13:52:22.989373+00:00 app[web.1]: !!!!!!!!!   EXISTING MODELS WERE FOUND  !!!!!!!!!
2019-01-08T13:52:23.069140+00:00 app[web.1]: ERROR:django.request:Internal Server Error: /tool/main_menu/
2019-01-08T13:52:23.069144+00:00 app[web.1]: Traceback (most recent call last):
2019-01-08T13:52:23.069152+00:00 app[web.1]: File "/app/.heroku/python/lib/python3.6/site-packages/django/db/backends/utils.py", line 85, in _execute
2019-01-08T13:52:23.069154+00:00 app[web.1]: return self.cursor.execute(sql, params)
2019-01-08T13:52:23.069157+00:00 app[web.1]: psycopg2.ProgrammingError: column collection_simulation_model.is_private does not exist
2019-01-08T13:52:23.069160+00:00 app[web.1]: LINE 1: ...pdated", "collection_simulation_model"."user_id", "collectio...
2019-01-08T13:52:23.069161+00:00 app[web.1]: ^
2019-01-08T13:52:23.069164+00:00 app[web.1]: 
2019-01-08T13:52:23.069165+00:00 app[web.1]: 
2019-01-08T13:52:23.069167+00:00 app[web.1]: The above exception was the direct cause of the following exception:
2019-01-08T13:52:23.069169+00:00 app[web.1]: 
2019-01-08T13:52:23.069170+00:00 app[web.1]: Traceback (most recent call last):
2019-01-08T13:52:23.069172+00:00 app[web.1]: File "/app/.heroku/python/lib/python3.6/site-packages/django/core/handlers/exception.py", line 35, in inner
2019-01-08T13:52:23.069173+00:00 app[web.1]: response = get_response(request)
2019-01-08T13:52:23.069175+00:00 app[web.1]: File "/app/.heroku/python/lib/python3.6/site-packages/django/core/handlers/base.py", line 128, in _get_response
2019-01-08T13:52:23.069177+00:00 app[web.1]: response = self.process_exception_by_middleware(e, request)
2019-01-08T13:52:23.069179+00:00 app[web.1]: File "/app/.heroku/python/lib/python3.6/site-packages/django/core/handlers/base.py", line 126, in _get_response
2019-01-08T13:52:23.069181+00:00 app[web.1]: response = wrapped_callback(request, *callback_args, **callback_kwargs)
2019-01-08T13:52:23.069182+00:00 app[web.1]: File "/app/.heroku/python/lib/python3.6/site-packages/django/contrib/auth/decorators.py", line 21, in _wrapped_view
2019-01-08T13:52:23.069183+00:00 app[web.1]: return view_func(request, *args, **kwargs)
2019-01-08T13:52:23.069185+00:00 app[web.1]: File "/app/collection/views.py", line 68, in main_menu
2019-01-08T13:52:23.069187+00:00 app[web.1]: print("!!!!!!!!!   NUMBER OF EXISTING MODELS: %s  !!!!!!!!!" % len(models))
2019-01-08T13:52:23.069188+00:00 app[web.1]: File "/app/.heroku/python/lib/python3.6/site-packages/django/db/models/query.py", line 254, in __len__
2019-01-08T13:52:23.069190+00:00 app[web.1]: self._fetch_all()
2019-01-08T13:52:23.069192+00:00 app[web.1]: File "/app/.heroku/python/lib/python3.6/site-packages/django/db/models/query.py", line 1179, in _fetch_all
2019-01-08T13:52:23.069193+00:00 app[web.1]: self._result_cache = list(self._iterable_class(self))
2019-01-08T13:52:23.069195+00:00 app[web.1]: File "/app/.heroku/python/lib/python3.6/site-packages/django/db/models/query.py", line 53, in __iter__
2019-01-08T13:52:23.069196+00:00 app[web.1]: results = compiler.execute_sql(chunked_fetch=self.chunked_fetch, chunk_size=self.chunk_size)
2019-01-08T13:52:23.069198+00:00 app[web.1]: File "/app/.heroku/python/lib/python3.6/site-packages/django/db/models/sql/compiler.py", line 1068, in execute_sql
2019-01-08T13:52:23.069199+00:00 app[web.1]: cursor.execute(sql, params)
2019-01-08T13:52:23.069201+00:00 app[web.1]: File "/app/.heroku/python/lib/python3.6/site-packages/django/db/backends/utils.py", line 68, in execute
2019-01-08T13:52:23.069202+00:00 app[web.1]: return self._execute_with_wrappers(sql, params, many=False, executor=self._execute)
2019-01-08T13:52:23.069204+00:00 app[web.1]: File "/app/.heroku/python/lib/python3.6/site-packages/django/db/backends/utils.py", line 77, in _execute_with_wrappers
2019-01-08T13:52:23.069206+00:00 app[web.1]: return executor(sql, params, many, context)
2019-01-08T13:52:23.069207+00:00 app[web.1]: File "/app/.heroku/python/lib/python3.6/site-packages/django/db/backends/utils.py", line 85, in _execute
2019-01-08T13:52:23.069209+00:00 app[web.1]: return self.cursor.execute(sql, params)
2019-01-08T13:52:23.069211+00:00 app[web.1]: File "/app/.heroku/python/lib/python3.6/site-packages/django/db/utils.py", line 89, in __exit__
2019-01-08T13:52:23.069212+00:00 app[web.1]: raise dj_exc_value.with_traceback(traceback) from exc_value
2019-01-08T13:52:23.069214+00:00 app[web.1]: File "/app/.heroku/python/lib/python3.6/site-packages/django/db/backends/utils.py", line 85, in _execute
2019-01-08T13:52:23.069215+00:00 app[web.1]: return self.cursor.execute(sql, params)
2019-01-08T13:52:23.069217+00:00 app[web.1]: django.db.utils.ProgrammingError: column collection_simulation_model.is_private does not exist
2019-01-08T13:52:23.069219+00:00 app[web.1]: LINE 1: ...pdated", "collection_simulation_model"."user_id", "collectio...
2019-01-08T13:52:23.069220+00:00 app[web.1]: ^
2019-01-08T13:52:23.069229+00:00 app[web.1]: 
